Workbook

Sheet Scoring
A1: Updated: | B1: 46269 | C1: LEAGUE SETTINGS & SCORING INPUTS
A2: INPUT YOUR LEAGUE SCORING HERE | I2: LEAGUE & ROSTER SETTINGS
A3: Setting: | B3: Points: | C3: DESCRIPTION | I3: #TEAMS: | J3: QB: | K3: RB: | L3: WR: | M3: TE: | N3: FLEX: | O3: BENCH: | P3: SUPERFLEX:
A4: PASSING | I4: 10 | J4: 1 | K4: 2 | L4: 2 | M4: 1 | N4: 1 | O4: 6 | P4: 0
A5: PassINCMP | B5: 0 | C5: Points Per Pass Incompletion (Use a Negative, Default is 0) | I5: ADVANCED SETTINGS
A6: PassCMP | B6: 0 | C6: Points Per Pass Completion (Default is 0) | I6: Snake OR Auction | K6: Snake | L6: ESTIMATED KEEPER SAVINGS
A7: PassYDS | B7: 25 | C7: Passing Yards Per 1 Point (Default is 25) | I7: Budget: | K7: 200 | L7: Est. Total Saved (Auction Keepers) | P7: 0
A8: PassTDs | B8: 4 | C8: Points Per Passing Touchdown (Default is 4) | I8: In the Yellow Cell (Dropdown) Change from SNAKE to AUCTION if you want AUCTION Values.
A9: INTS | B9: -1 | C9: Points Per Interception (Use a Negative, Default is -2)
A10: SACKS | B10: 0 | C10: Points Per Sack (Use a Negative, Default is 0)
A11: RUSHING
A12: RushATT | B12: 0 | C12: Points Per Rush Attempt (Default is 0)
A13: RushYDS | B13: 10 | C13: Rushing Yards Per 1 Point (Default is 10)
A14: RushTDS | B14: 6 | C14: Points Per Rushing Touchdown (Default is 6)
A15: RECEIVING
A16: RB PPR | B16: 0.5 | C16: RB Points Per Reception (Examples: 0 , .5 , 1)
A17: WR PPR | B17: 0.5 | C17: WR Points Per Reception (Examples: 0 , .5 , 1)
A18: TE PPR | B18: 0.5 | C18: TE Points Per Reception (Examples: 0 , .5 , 1)
A19: RecYDS | B19: 10 | C19: Receiving Yards Per 1 Point (Default is 10)
A20: RecTDS | B20: 6 | C20: Points Per Receiving Touchdown (Default is 6)
A21: OTHER:
A22: FL | B22: -2 | C22: Points Per Fumble Lost (Use a Negative, Default is -2)
A23: Pass1D | B23: 0 | C23: Points Per Passing 1st Down (Default is 0)
A24: Rush1D | B24: 0 | C24: Points Per Rushing 1st Down (Default is 0)
A25: Rec1D | B25: 0 | C25: Points Per Receiving 1st Down (Default is 0)
A28: 🔒 CALCULATED VALUES BELOW — DO NOT EDIT (used internally for VBD/Auction math)
A29: QBs: | B29: PassCMP | C29: PassYDS | D29: PassTDs | E29: INTS | F29: RushATT | G29: RushYDS | H29: RushTDS | I29: FL | J29: Pass1D | K29: Rush1D
A30: POINTS | B30: =B6 -> 0 | C30: =B7 -> 25 | D30: =B8 -> 4 | E30: =B9 -> -1 | F30: =B12 -> 0 | G30: =B13 -> 10 | H30: =B14 -> 6 | I30: =B22 -> -2 | J30: =B23 -> 0 | K30: =B24 -> 0
A31: RBs: | B31: RushATT | C31: RushYDS | D31: RushTDS | E31: PPR | F31: RecYDS | G31: RecTDS | H31: FL | I31: Rush1D | J31: Rec1D
A32: POINTS | B32: =B12 -> 0 | C32: =B13 -> 10 | D32: =B14 -> 6 | E32: =B16 -> 0.5 | F32: =B19 -> 10 | G32: =B20 -> 6 | H32: =B22 -> -2 | I32: =B24 -> 0 | J32: =B25 -> 0
A33: WRs: | B33: PPR | C33: RecYDS | D33: RecTDS | E33: RushATT | F33: RushYDS | G33: RushTDS | H33: FL | I33: Rush1D | J33: Rec1D
A34: POINTS | B34: =B17 -> 0.5 | C34: =B19 -> 10 | D34: =B20 -> 6 | E34: =B12 -> 0 | F34: =B13 -> 10 | G34: =B14 -> 6 | H34: =B22 -> -2 | I34: =B24 -> 0 | J34: =B25 -> 0
A35: TEs: | B35: PPR | C35: RecYDS | D35: RecTDS | E35: FL | F35: Rec1D
A36: POINTS | B36: =B18 -> 0.5 | C36: =B19 -> 10 | D36: =B20 -> 6 | E36: =B22 -> -2 | F36: =B25 -> 0
A38: Baseline Calcs
A39: #TEAMS: | B39: QB: | C39: RB: | D39: WR: | E39: TE: | F39: FLEX:
A40: =I4 -> 10 | B40: =J4+P4 -> 1 | C40: =K4 -> 2 | D40: =L4 -> 2 | E40: =M4 -> 1 | F40: =N4+I38 -> 1
A41: Roster | B41: =(J4+P4)*I4 -> 10 | C41: =ROUND(K4*I4*1.267,0) -> 25 | D41: =ROUND(L4*I4*1.23,0) -> 25 | E41: =ROUND(M4*I4*1.2,0) -> 12 | F41: =ROUND(N4*I4*1.4,0) -> 14
A42: Flex: | B42: 0 | C42: =FLEX!E1 -> 6 | D42: =FLEX!G1 -> 8 | E42: =FLEX!I1 -> 0
A43: Baselines: | B43: =ROUND(B41*1.17,) -> 12 | C43: =C41+C42 -> 31 | D43: =D41+D42 -> 33 | E43: =E41+E42 -> 12
...

Sheet DraftSheet
B1: ="DRAFTSHEET - "&Scoring!I4&" Team - "&Scoring!B17&" PPR - "&Scoring!J4&"QB("&Aggregate!B1&") / "&Scoring!K4&"RB("&Aggregate!P1&") / "&Scoring!L4&"WR("&Aggregate!AD1&") / "&Scoring!M4&"TE("&Aggregate!AR1&") / "&Scoring!N4&"[RB/WR/TE]" -> DRAFTSHEET - 10 Team - 0.5 PPR - 1QB(12) / 2RB(31) / 2WR(33) / 1TE(12) / 1[RB/WR/TE] | AF1: PLAYER SEARCH
B2: ="Passing: "&Scoring!B8&" PPTD, "&ROUND(1/Scoring!B7,2)&" PPY, "&Scoring!B9&" Int | Rushing: "&Scoring!B14&" PPTD, "&ROUND(1/Scoring!B13,2)&" PPY | Receiving: "&Scoring!B20&" PPTD, "&ROUND(1/Scoring!B19,2)&" PPY, "&Scoring!B17&" PPR | Draft: use 'x' if drafted by someone else, 'o' if drafted by you | Updated: "&TEXT(TODAY(),"yyyy-mm-dd") -> Passing: 4 PPTD, 0.04 PPY, -1 Int | Rushing: 6 PPTD, 0.1 PPY | Receiving: 6 PPTD, 0.1 PPY, 0.5 PPR | Draft: use 'x' if drafted by someone else, 'o' if drafted by you | Updated: 2026-09-05 | AF2: TYPE NAME HERE: | AH2: =IF($AG$2="","",IFERROR(MATCH("*"&$AG$2&"*",C5:C44,0)+4,""))
B3: QUARTERBACK | L3: RUNNING BACK | V3: WIDE RECEIVER | AF3: Position: | AG3: =IF($AG$2="","",IF(AH2<>"","QB",IF(AH3<>"","RB",IF(AH4<>"","WR",IF(AH5<>"","TE","Not Found"))))) | AH3: =IF($AG$2="","",IFERROR(MATCH("*"&$AG$2&"*",M5:M84,0)+4,""))
B4: TIER | C4: NAME | D4: TM/BYE | E4: PTS | F4: VALUE | G4: PS | H4: ECR | I4: DRAFT | L4: TIER | M4: NAME | N4: TM/BYE | O4: PTS | P4: VALUE | Q4: PS | R4: ECR | S4: DRAFT | V4: TIER | W4: NAME | X4: TM/BYE | Y4: PTS | Z4: VALUE | AA4: PS | AB4: ECR | AC4: DRAFT | AF4: Tier: | AG4: =IF($AG$2="","",IF(AH2<>"",INDEX(B:B,AH2),IF(AH3<>"",INDEX(L:L,AH3),IF(AH4<>"",INDEX(V:V,AH4),IF(AH5<>"",INDEX(B:B,AH5),""))))) | AH4: =IF($AG$2="","",IFERROR(MATCH("*"&$AG$2&"*",W5:W84,0)+4,""))
B5: =IFERROR(VLOOKUP(Table9[[#This Row],[NAME]],Aggregate!$B:$M,11,FALSE()),"") -> 1 | C5: =Aggregate!B3 -> Josh Allen | D5: =VLOOKUP(Table9[[#This Row],[NAME]],Aggregate!B:M,4,FALSE()) -> BUF/7 | E5: =IFERROR(VLOOKUP(Table9[[#This Row],[NAME]],Aggregate!$B:$M,8,FALSE()),"") -> 324.97794 | F5: =IF(Scoring!$K$6="Auction",IFERROR(VLOOKUP(Table9[[#This Row],[NAME]],Aggregate!$B:$M,10,FALSE()),""),IFERROR(VLOOKUP(Table9[[#This Row],[NAME]],Aggregate!$B:$M,9,FALSE()),"")) -> 56.598576 | G5: =SUMIFS(J6:$J$44,I6:$I$44,"<>x",I6:$I$44,"<>o",J6:$J$44,">0")/Aggregate!$J$1 -> 0.59269413 | H5: =VLOOKUP(Table9[[#This Row],[NAME]],ECR!C:E,3,FALSE()) -> QB1 | J5: =VLOOKUP(C5,Aggregate!B:J,9,FALSE()) -> 56.598576 | L5: =IFERROR(VLOOKUP(Table10[[#This Row],[NAME]],Aggregate!$P:$AA,11,FALSE()),"") -> 1 | M5: =Aggregate!P3 -> Jahmyr Gibbs | N5: =VLOOKUP(Table10[[#This Row],[NAME]],Aggregate!P:AA,4,FALSE()) -> DET/6 | O5: =IFERROR(VLOOKUP(Table10[[#This Row],[NAME]],Aggregate!$P:$AA,8,FALSE()),"") -> 291.35319 | P5: =IF(Scoring!$K$6="Auction",IFERROR(VLOOKUP(Table10[[#This Row],[NAME]],Aggregate!$P:$AA,10,FALSE()),""),IFERROR(VLOOKUP(Table10[[#This Row],[NAME]],Aggregate!$P:$AA,9,FALSE()),"")) -> 163.80745 | Q5: =SUMIFS(T6:$T$84,S6:$S$84,"<>x",S6:$S$84,"<>o",T6:$T$84,">0")/Aggregate!$X$1 -> 0.91151838 | R5: =VLOOKUP(Table10[[#This Row],[NAME]],ECR!C:E,3,FALSE()) -> RB1 | T5: =VLOOKUP(M5,Aggregate!P:X,9,FALSE()) -> 163.80745 | V5: =IFERROR(VLOOKUP(Table11[[#This Row],[NAME]],Aggregate!$AD:$AO,11,FALSE()),"") -> 1 | W5: =Aggregate!AD4 -> Puka Nacua | X5: =VLOOKUP(Table11[[#This Row],[NAME]],Aggregate!AD:AO,4,FALSE()) -> LAR/11 | Y5: =IFERROR(VLOOKUP(Table11[[#This Row],[NAME]],Aggregate!$AD:$AO,8,FALSE()),"") -> 248.43324 | Z5: =IF(Scoring!$K$6="Auction",IFERROR(VLOOKUP(Table11[[#This Row],[NAME]],Aggregate!$AD:$AO,10,FALSE()),""),IFERROR(VLOOKUP(Table11[[#This Row],[NAME]],Aggregate!$AD:$AO,9,FALSE()),"")) -> 122.75536 | AA5: =SUMIFS(AD6:$AD$84,AC6:$AC$84,"<>x",AC6:$AC$84,"<>o",AD6:$AD$84,">0")/Aggregate!$AL$1 -> 0.91194216 | AB5: =VLOOKUP(Table11[[#This Row],[NAME]],ECR!C:E,3,FALSE()) -> WR2 | AD5: =VLOOKUP(W5,Aggregate!AD:AL,9,FALSE()) -> 122.75536 | AF5: Name: | AG5: =IF($AG$2="","",IF(AH2<>"",INDEX(C:C,AH2),IF(AH3<>"",INDEX(M:M,AH3),IF(AH4<>"",INDEX(W:W,AH4),IF(AH5<>"",INDEX(C:C,AH5),""))))) | AH5: =IF($AG$2="","",IFERROR(MATCH("*"&$AG$2&"*",C48:C84,0)+47,""))
B6: =IFERROR(VLOOKUP(Table9[[#This Row],[NAME]],Aggregate!$B:$M,11,FALSE()),"") -> 2 | C6: =Aggregate!B4 -> Lamar Jackson | D6: =VLOOKUP(Table9[[#This Row],[NAME]],Aggregate!B:M,4,FALSE()) -> BAL/13 | E6: =IFERROR(VLOOKUP(Table9[[#This Row],[NAME]],Aggregate!$B:$M,8,FALSE()),"") -> 286.78631 | F6: =IF(Scoring!$K$6="Auction",IFERROR(VLOOKUP(Table9[[#This Row],[NAME]],Aggregate!$B:$M,10,FALSE()),""),IFERROR(VLOOKUP(Table9[[#This Row],[NAME]],Aggregate!$B:$M,9,FALSE()),"")) -> 18.406947 | G6: =SUMIFS(J7:$J$44,I7:$I$44,"<>x",I7:$I$44,"<>o",J7:$J$44,">0")/Aggregate!$J$1 -> 0.46023042 | H6: =VLOOKUP(Table9[[#This Row],[NAME]],ECR!C:E,3,FALSE()) -> QB2 | J6: =VLOOKUP(C6,Aggregate!B:J,9,FALSE()) -> 18.406947 | L6: =IFERROR(VLOOKUP(Table10[[#This Row],[NAME]],Aggregate!$P:$AA,11,FALSE()),"") -> 1 | M6: =Aggregate!P4 -> Bijan Robinson | N6: =VLOOKUP(Table10[[#This Row],[NAME]],Aggregate!P:AA,4,FALSE()) -> ATL/11 | O6: =IFERROR(VLOOKUP(Table10[[#This Row],[NAME]],Aggregate!$P:$AA,8,FALSE()),"") -> 270.34108 | P6: =IF(Scoring!$K$6="Auction",IFERROR(VLOOKUP(Table10[[#This Row],[NAME]],Aggregate!$P:$AA,10,FALSE()),""),IFERROR(VLOOKUP(Table10[[#This Row],[NAME]],Aggregate!$P:$AA,9,FALSE()),"")) -> 142.79534 | Q6: =SUMIFS(T7:$T$84,S7:$S$84,"<>x",S7:$S$84,"<>o",T7:$T$84,">0")/Aggregate!$X$1 -> 0.83438658 | R6: =VLOOKUP(Table10[[#This Row],[NAME]],ECR!C:E,3,FALSE()) -> RB2 | T6: =VLOOKUP(M6,Aggregate!P:X,9,FALSE()) -> 142.79534 | V6: =IFERROR(VLOOKUP(Table11[[#This Row],[NAME]],Aggregate!$AD:$AO,11,FALSE()),"") -> 1 | W6: =Aggregate!AD3 -> Ja'Marr Chase | X6: =VLOOKUP(Table11[[#This Row],[NAME]],Aggregate!AD:AO,4,FALSE()) -> CIN/6 | Y6: =IFERROR(VLOOKUP(Table11[[#This Row],[NAME]],Aggregate!$AD:$AO,8,FALSE()),"") -> 246.79195 | Z6: =IF(Scoring!$K$6="Auction",IFERROR(VLOOKUP(Table11[[#This Row],[NAME]],Aggregate!$AD:$AO,10,FALSE()),""),IFERROR(VLOOKUP(Table11[[#This Row],[NAME]],Aggregate!$AD:$AO,9,FALSE()),"")) -> 121.11407 | AA6: =SUMIFS(AD7:$AD$84,AC7:$AC$84,"<>x",AC7:$AC$84,"<>o",AD7:$AD$84,">0")/Aggregate!$AL$1 -> 0.8250617 | AB6: =VLOOKUP(Table11[[#This Row],[NAME]],ECR!C:E,3,FALSE()) -> WR1 | AD6: =VLOOKUP(W6,Aggregate!AD:AL,9,FALSE()) -> 121.11407 | AF6: TM/BYE: | AG6: =IF($AG$2="","",IF(AH2<>"",INDEX(D:D,AH2),IF(AH3<>"",INDEX(N:N,AH3),IF(AH4<>"",INDEX(X:X,AH4),IF(AH5<>"",INDEX(D:D,AH5),"")))))
B7: =IFERROR(VLOOKUP(Table9[[#This Row],[NAME]],Aggregate!$B:$M,11,FALSE()),"") -> 2 | C7: =Aggregate!B7 -> Jalen Hurts | D7: =VLOOKUP(Table9[[#This Row],[NAME]],Aggregate!B:M,4,FALSE()) -> PHI/10 | E7: =IFERROR(VLOOKUP(Table9[[#This Row],[NAME]],Aggregate!$B:$M,8,FALSE()),"") -> 284.31265 | F7: =IF(Scoring!$K$6="Auction",IFERROR(VLOOKUP(Table9[[#This Row],[NAME]],Aggregate!$B:$M,10,FALSE()),""),IFERROR(VLOOKUP(Table9[[#This Row],[NAME]],Aggregate!$B:$M,9,FALSE()),"")) -> 15.933283 | G7: =SUMIFS(J8:$J$44,I8:$I$44,"<>x",I8:$I$44,"<>o",J8:$J$44,">0")/Aggregate!$J$1 -> 0.34556818 | H7: =VLOOKUP(Table9[[#This Row],[NAME]],ECR!C:E,3,FALSE()) -> QB5 | J7: =VLOOKUP(C7,Aggregate!B:J,9,FALSE()) -> 15.933283 | L7: =IFERROR(VLOOKUP(Table10[[#This Row],[NAME]],Aggregate!$P:$AA,11,FALSE()),"") -> 2 | M7: =Aggregate!P5 -> Jonathan Taylor | N7: =VLOOKUP(Table10[[#This Row],[NAME]],Aggregate!P:AA,4,FALSE()) -> IND/13 | O7: =IFERROR(VLOOKUP(Table10[[#This Row],[NAME]],Aggregate!$P:$AA,8,FALSE()),"") -> 249.19215 | P7: =IF(Scoring!$K$6="Auction",IFERROR(VLOOKUP(Table10[[#This Row],[NAME]],Aggregate!$P:$AA,10,FALSE()),""),IFERROR(VLOOKUP(Table10[[#This Row],[NAME]],Aggregate!$P:$AA,9,FALSE()),"")) -> 121.64642 | Q7: =SUMIFS(T8:$T$84,S8:$S$84,"<>x",S8:$S$84,"<>o",T8:$T$84,">0")/Aggregate!$X$1 -> 0.7686785 | R7: =VLOOKUP(Table10[[#This Row],[NAME]],ECR!C:E,3,FALSE()) -> RB3 | T7: =VLOOKUP(M7,Aggregate!P:X,9,FALSE()) -> 121.64642 | V7: =IFERROR(VLOOKUP(Table11[[#This Row],[NAME]],Aggregate!$AD:$AO,11,FALSE()),"") -> 1 | W7: =Aggregate!AD5 -> Jaxon Smith-Njigba | X7: =VLOOKUP(Table11[[#This Row],[NAME]],Aggregate!AD:AO,4,FALSE()) -> SEA/11 | Y7: =IFERROR(VLOOKUP(Table11[[#This Row],[NAME]],Aggregate!$AD:$AO,8,FALSE()),"") -> 240.06534 | Z7: =IF(Scoring!$K$6="Auction",IFERROR(VLOOKUP(Table11[[#This Row],[NAME]],Aggregate!$AD:$AO,10,FALSE()),""),IFERROR(VLOOKUP(Table11[[#This Row],[NAME]],Aggregate!$AD:$AO,9,FALSE()),"")) -> 114.38746 | AA7: =SUMIFS(AD8:$AD$84,AC8:$AC$84,"<>x",AC8:$AC$84,"<>o",AD8:$AD$84,">0")/Aggregate!$AL$1 -> 0.74300653 | AB7: =VLOOKUP(Table11[[#This Row],[NAME]],ECR!C:E,3,FALSE()) -> WR3 | AD7: =VLOOKUP(W7,Aggregate!AD:AL,9,FALSE()) -> 114.38746 | AF7: PTS: | AG7: =IF($AG$2="","",IF(AH2<>"",INDEX(E:E,AH2),IF(AH3<>"",INDEX(O:O,AH3),IF(AH4<>"",INDEX(Y:Y,AH4),IF(AH5<>"",INDEX(E:E,AH5),"")))))
B8: =IFERROR(VLOOKUP(Table9[[#This Row],[NAME]],Aggregate!$B:$M,11,FALSE()),"") -> 3 | C8: =Aggregate!B5 -> Drake Maye | D8: =VLOOKUP(Table9[[#This Row],[NAME]],Aggregate!B:M,4,FALSE()) -> NE/11 | E8: =IFERROR(VLOOKUP(Table9[[#This Row],[NAME]],Aggregate!$B:$M,8,FALSE()),"") -> 282.82321 | F8: =IF(Scoring!$K$6="Auction",IFERROR(VLOOKUP(Table9[[#This Row],[NAME]],Aggregate!$B:$M,10,FALSE()),""),IFERROR(VLOOKUP(Table9[[#This Row],[NAME]],Aggregate!$B:$M,9,FALSE()),"")) -> 14.443841 | G8: =SUMIFS(J9:$J$44,I9:$I$44,"<>x",I9:$I$44,"<>o",J9:$J$44,">0")/Aggregate!$J$1 -> 0.24162456 | H8: =VLOOKUP(Table9[[#This Row],[NAME]],ECR!C:E,3,FALSE()) -> QB3 | J8: =VLOOKUP(C8,Aggregate!B:J,9,FALSE()) -> 14.443841 | L8: =IFERROR(VLOOKUP(Table10[[#This Row],[NAME]],Aggregate!$P:$AA,11,FALSE()),"") -> 2 | M8: =Aggregate!P6 -> Christian McCaffrey | N8: =VLOOKUP(Table10[[#This Row],[NAME]],Aggregate!P:AA,4,FALSE()) -> SF/8 | O8: =IFERROR(VLOOKUP(Table10[[#This Row],[NAME]],Aggregate!$P:$AA,8,FALSE()),"") -> 248.89741 | P8: =IF(Scoring!$K$6="Auction",IFERROR(VLOOKUP(Table10[[#This Row],[NAME]],Aggregate!$P:$AA,10,FALSE()),""),IFERROR(VLOOKUP(Table10[[#This Row],[NAME]],Aggregate!$P:$AA,9,FALSE()),"")) -> 121.35168 | Q8: =SUMIFS(T9:$T$84,S9:$S$84,"<>x",S9:$S$84,"<>o",T9:$T$84,">0")/Aggregate!$X$1 -> 0.70312963 | R8: =VLOOKUP(Table10[[#This Row],[NAME]],ECR!C:E,3,FALSE()) -> RB4 | T8: =VLOOKUP(M8,Aggregate!P:X,9,FALSE()) -> 121.35168 | V8: =IFERROR(VLOOKUP(Table11[[#This Row],[NAME]],Aggregate!$AD:$AO,11,FALSE()),"") -> 2 | W8: =Aggregate!AD6 -> Amon-Ra St. Brown | X8: =VLOOKUP(Table11[[#This Row],[NAME]],Aggregate!AD:AO,4,FALSE()) -> DET/6 | Y8: =IFERROR(VLOOKUP(Table11[[#This Row],[NAME]],Aggregate!$AD:$AO,8,FALSE()),"") -> 230.24461 | Z8: =IF(Scoring!$K$6="Auction",IFERROR(VLOOKUP(Table11[[#This Row],[NAME]],Aggregate!$AD:$AO,10,FALSE()),""),IFERROR(VLOOKUP(Table11[[#This Row],[NAME]],Aggregate!$AD:$AO,9,FALSE()),"")) -> 104.56673 | AA8: =SUMIFS(AD9:$AD$84,AC9:$AC$84,"<>x",AC9:$AC$84,"<>o",AD9:$AD$84,">0")/Aggregate!$AL$1 -> 0.6679962 | AB8: =VLOOKUP(Table11[[#This Row],[NAME]],ECR!C:E,3,FALSE()) -> WR4 | AD8: =VLOOKUP(W8,Aggregate!AD:AL,9,FALSE()) -> 104.56673 | AF8: VALUE: | AG8: =IF($AG$2="","",IF(AH2<>"",INDEX(F:F,AH2),IF(AH3<>"",INDEX(P:P,AH3),IF(AH4<>"",INDEX(Z:Z,AH4),IF(AH5<>"",INDEX(F:F,AH5),"")))))
B9: =IFERROR(VLOOKUP(Table9[[#This Row],[NAME]],Aggregate!$B:$M,11,FALSE()),"") -> 3 | C9: =Aggregate!B8 -> Jayden Daniels | D9: =VLOOKUP(Table9[[#This Row],[NAME]],Aggregate!B:M,4,FALSE()) -> WAS/7 | E9: =IFERROR(VLOOKUP(Table9[[#This Row],[NAME]],Aggregate!$B:$M,8,FALSE()),"") -> 282.1602 | F9: =IF(Scoring!$K$6="Auction",IFERROR(VLOOKUP(Table9[[#This Row],[NAME]],Aggregate!$B:$M,10,FALSE()),""),IFERROR(VLOOKUP(Table9[[#This Row],[NAME]],Aggregate!$B:$M,9,FALSE()),"")) -> 13.780832 | G9: =SUMIFS(J10:$J$44,I10:$I$44,"<>x",I10:$I$44,"<>o",J10:$J$44,">0")/Aggregate!$J$1 -> 0.14245221 | H9: =VLOOKUP(Table9[[#This Row],[NAME]],ECR!C:E,3,FALSE()) -> QB6 | J9: =VLOOKUP(C9,Aggregate!B:J,9,FALSE()) -> 13.780832 | L9: =IFERROR(VLOOKUP(Table10[[#This Row],[NAME]],Aggregate!$P:$AA,11,FALSE()),"") -> 3 | M9: =Aggregate!P7 -> James Cook III | N9: =VLOOKUP(Table10[[#This Row],[NAME]],Aggregate!P:AA,4,FALSE()) -> BUF/7 | O9: =IFERROR(VLOOKUP(Table10[[#This Row],[NAME]],Aggregate!$P:$AA,8,FALSE()),"") -> 218.4356 | P9: =IF(Scoring!$K$6="Auction",IFERROR(VLOOKUP(Table10[[#This Row],[NAME]],Aggregate!$P:$AA,10,FALSE()),""),IFERROR(VLOOKUP(Table10[[#This Row],[NAME]],Aggregate!$P:$AA,9,FALSE()),"")) -> 90.889864 | Q9: =SUMIFS(T10:$T$84,S10:$S$84,"<>x",S10:$S$84,"<>o",T10:$T$84,">0")/Aggregate!$X$1 -> 0.6540349 | R9: =VLOOKUP(Table10[[#This Row],[NAME]],ECR!C:E,3,FALSE()) -> RB5 | T9: =VLOOKUP(M9,Aggregate!P:X,9,FALSE()) -> 90.889864 | V9: =IFERROR(VLOOKUP(Table11[[#This Row],[NAME]],Aggregate!$AD:$AO,11,FALSE()),"") -> 3 | W9: =Aggregate!AD8 -> Justin Jefferson | X9: =VLOOKUP(Table11[[#This Row],[NAME]],Aggregate!AD:AO,4,FALSE()) -> MIN/6 | Y9: =IFERROR(VLOOKUP(Table11[[#This Row],[NAME]],Aggregate!$AD:$AO,8,FALSE()),"") -> 195.85264 | Z9: =IF(Scoring!$K$6="Auction",IFERROR(VLOOKUP(Table11[[#This Row],[NAME]],Aggregate!$AD:$AO,10,FALSE()),""),IFERROR(VLOOKUP(Table11[[#This Row],[NAME]],Aggregate!$AD:$AO,9,FALSE()),"")) -> 70.174765 | AA9: =SUMIFS(AD10:$AD$84,AC10:$AC$84,"<>x",AC10:$AC$84,"<>o",AD10:$AD$84,">0")/Aggregate!$AL$1 -> 0.61765674 | AB9: =VLOOKUP(Table11[[#This Row],[NAME]],ECR!C:E,3,FALSE()) -> WR6 | AD9: =VLOOKUP(W9,Aggregate!AD:AL,9,FALSE()) -> 70.174765 | AF9: PS: | AG9: =IF($AG$2="","",IF(AH2<>"",INDEX(G:G,AH2),IF(AH3<>"",INDEX(Q:Q,AH3),IF(AH4<>"",INDEX(AA:AA,AH4),IF(AH5<>"",INDEX(G:G,AH5),"")))))
B10: =IFERROR(VLOOKUP(Table9[[#This Row],[NAME]],Aggregate!$B:$M,11,FALSE()),"") -> 4 | C10: =Aggregate!B6 -> Joe Burrow | D10: =VLOOKUP(Table9[[#This Row],[NAME]],Aggregate!B:M,4,FALSE()) -> CIN/6 | E10: =IFERROR(VLOOKUP(Table9[[#This Row],[NAME]],Aggregate!$B:$M,8,FALSE()),"") -> 278.52258 | F10: =IF(Scoring!$K$6="Auction",IFERROR(VLOOKUP(Table9[[#This Row],[NAME]],Aggregate!$B:$M,10,FALSE()),""),IFERROR(VLOOKUP(Table9[[#This Row],[NAME]],Aggregate!$B:$M,9,FALSE()),"")) -> 10.143214 | G10: =SUMIFS(J11:$J$44,I11:$I$44,"<>x",I11:$I$44,"<>o",J11:$J$44,">0")/Aggregate!$J$1 -> 0.069457609 | H10: =VLOOKUP(Table9[[#This Row],[NAME]],ECR!C:E,3,FALSE()) -> QB4 | J10: =VLOOKUP(C10,Aggregate!B:J,9,FALSE()) -> 10.143214 | L10: =IFERROR(VLOOKUP(Table10[[#This Row],[NAME]],Aggregate!$P:$AA,11,FALSE()),"") -> 3 | M10: =Aggregate!P10 -> De'Von Achane | N10: =VLOOKUP(Table10[[#This Row],[NAME]],Aggregate!P:AA,4,FALSE()) -> MIA/6 | O10: =IFERROR(VLOOKUP(Table10[[#This Row],[NAME]],Aggregate!$P:$AA,8,FALSE()),"") -> 218.14299 | P10: =IF(Scoring!$K$6="Auction",IFERROR(VLOOKUP(Table10[[#This Row],[NAME]],Aggregate!$P:$AA,10,FALSE()),""),IFERROR(VLOOKUP(Table10[[#This Row],[NAME]],Aggregate!$P:$AA,9,FALSE()),"")) -> 90.597251 | Q10: =SUMIFS(T11:$T$84,S11:$S$84,"<>x",S11:$S$84,"<>o",T11:$T$84,">0")/Aggregate!$X$1 -> 0.60509823 | R10: =VLOOKUP(Table10[[#This Row],[NAME]],ECR!C:E,3,FALSE()) -> RB8 | T10: =VLOOKUP(M10,Aggregate!P:X,9,FALSE()) -> 90.597251 | V10: =IFERROR(VLOOKUP(Table11[[#This Row],[NAME]],Aggregate!$AD:$AO,11,FALSE()),"") -> 3 | W10: =Aggregate!AD7 -> CeeDee Lamb | X10: =VLOOKUP(Table11[[#This Row],[NAME]],Aggregate!AD:AO,4,FALSE()) -> DAL/14 | Y10: =IFERROR(VLOOKUP(Table11[[#This Row],[NAME]],Aggregate!$AD:$AO,8,FALSE()),"") -> 195.04431 | Z10: =IF(Scoring!$K$6="Auction",IFERROR(VLOOKUP(Table11[[#This Row],[NAME]],Aggregate!$AD:$AO,10,FALSE()),""),IFERROR(VLOOKUP(Table11[[#This Row],[NAME]],Aggregate!$AD:$AO,9,FALSE()),"")) -> 69.366434 | AA10: =SUMIFS(AD11:$AD$84,AC11:$AC$84,"<>x",AC11:$AC$84,"<>o",AD11:$AD$84,">0")/Aggregate!$AL$1 -> 0.56789714 | AB10: =VLOOKUP(Table11[[#This Row],[NAME]],ECR!C:E,3,FALSE()) -> WR5 | AD10: =VLOOKUP(W10,Aggregate!AD:AL,9,FALSE()) -> 69.366434 | AF10: ECR: | AG10: =IF($AG$2="","",IF(AH2<>"",INDEX(H:H,AH2),IF(AH3<>"",INDEX(R:R,AH3),IF(AH4<>"",INDEX(AB:AB,AH4),IF(AH5<>"",INDEX(H:H,AH5),"")))))
B11: =IFERROR(VLOOKUP(Table9[[#This Row],[NAME]],Aggregate!$B:$M,11,FALSE()),"") -> 5 | C11: =Aggregate!B11 -> Trevor Lawrence | D11: =VLOOKUP(Table9[[#This Row],[NAME]],Aggregate!B:M,4,FALSE()) -> JAC/7 | E11: =IFERROR(VLOOKUP(Table9[[#This Row],[NAME]],Aggregate!$B:$M,8,FALSE()),"") -> 272.07268 | F11: =IF(Scoring!$K$6="Auction",IFERROR(VLOOKUP(Table9[[#This Row],[NAME]],Aggregate!$B:$M,10,FALSE()),""),IFERROR(VLOOKUP(Table9[[#This Row],[NAME]],Aggregate!$B:$M,9,FALSE()),"")) -> 3.6933111 | G11: =SUMIFS(J12:$J$44,I12:$I$44,"<>x",I12:$I$44,"<>o",J12:$J$44,">0")/Aggregate!$J$1 -> 0.042879073 | H11: =VLOOKUP(Table9[[#This Row],[NAME]],ECR!C:E,3,FALSE()) -> QB9 | J11: =VLOOKUP(C11,Aggregate!B:J,9,FALSE()) -> 3.6933111 | L11: =IFERROR(VLOOKUP(Table10[[#This Row],[NAME]],Aggregate!$P:$AA,11,FALSE()),"") -> 3 | M11: =Aggregate!P13 -> Derrick Henry | N11: =VLOOKUP(Table10[[#This Row],[NAME]],Aggregate!P:AA,4,FALSE()) -> BAL/13 | O11: =IFERROR(VLOOKUP(Table10[[#This Row],[NAME]],Aggregate!$P:$AA,8,FALSE()),"") -> 215.59352 | P11: =IF(Scoring!$K$6="Auction",IFERROR(VLOOKUP(Table10[[#This Row],[NAME]],Aggregate!$P:$AA,10,FALSE()),""),IFERROR(VLOOKUP(Table10[[#This Row],[NAME]],Aggregate!$P:$AA,9,FALSE()),"")) -> 88.04778 | Q11: =SUMIFS(T12:$T$84,S12:$S$84,"<>x",S12:$S$84,"<>o",T12:$T$84,">0")/Aggregate!$X$1 -> 0.55753867 | R11: =VLOOKUP(Table10[[#This Row],[NAME]],ECR!C:E,3,FALSE()) -> RB11 | T11: =VLOOKUP(M11,Aggregate!P:X,9,FALSE()) -> 88.04778 | V11: =IFERROR(VLOOKUP(Table11[[#This Row],[NAME]],Aggregate!$AD:$AO,11,FALSE()),"") -> 3 | W11: =Aggregate!AD10 -> Drake London | X11: =VLOOKUP(Table11[[#This Row],[NAME]],Aggregate!AD:AO,4,FALSE()) -> ATL/11 | Y11: =IFERROR(VLOOKUP(Table11[[#This Row],[NAME]],Aggregate!$AD:$AO,8,FALSE()),"") -> 190.37802 | Z11: =IF(Scoring!$K$6="Auction",IFERROR(VLOOKUP(Table11[[#This Row],[NAME]],Aggregate!$AD:$AO,10,FALSE()),""),IFERROR(VLOOKUP(Table11[[#This Row],[NAME]],Aggregate!$AD:$AO,9,FALSE()),"")) -> 64.700141 | AA11: =SUMIFS(AD12:$AD$84,AC12:$AC$84,"<>x",AC12:$AC$84,"<>o",AD12:$AD$84,">0")/Aggregate!$AL$1 -> 0.52148488 | AB11: =VLOOKUP(Table11[[#This Row],[NAME]],ECR!C:E,3,FALSE()) -> WR8 | AD11: =VLOOKUP(W11,Aggregate!AD:AL,9,FALSE()) -> 64.700141 | AF11: Drafted?: | AG11: =IF($AG$2="","",IF(AH2<>"",IF(INDEX(I:I,AH2)="","Available",INDEX(I:I,AH2)),IF(AH3<>"",IF(INDEX(S:S,AH3)="","Available",INDEX(S:S,AH3)),IF(AH4<>"",IF(INDEX(AC:AC,AH4)="","Available",INDEX(AC:AC,AH4)),IF(AH5<>"",IF(INDEX(I:I,AH5)="","Available",INDEX(I:I,AH5)),"")))))
B12: =IFERROR(VLOOKUP(Table9[[#This Row],[NAME]],Aggregate!$B:$M,11,FALSE()),"") -> 5 | C12: =Aggregate!B12 -> Dak Prescott | D12: =VLOOKUP(Table9[[#This Row],[NAME]],Aggregate!B:M,4,FALSE()) -> DAL/14 | E12: =IFERROR(VLOOKUP(Table9[[#This Row],[NAME]],Aggregate!$B:$M,8,FALSE()),"") -> 270.40003 | F12: =IF(Scoring!$K$6="Auction",IFERROR(VLOOKUP(Table9[[#This Row],[NAME]],Aggregate!$B:$M,10,FALSE()),""),IFERROR(VLOOKUP(Table9[[#This Row],[NAME]],Aggregate!$B:$M,9,FALSE()),"")) -> 2.0206634 | G12: =SUMIFS(J13:$J$44,I13:$I$44,"<>x",I13:$I$44,"<>o",J13:$J$44,">0")/Aggregate!$J$1 -> 0.028337576 | H12: =VLOOKUP(Table9[[#This Row],[NAME]],ECR!C:E,3,FALSE()) -> QB10 | J12: =VLOOKUP(C12,Aggregate!B:J,9,FALSE()) -> 2.0206634 | L12: =IFERROR(VLOOKUP(Table10[[#This Row],[NAME]],Aggregate!$P:$AA,11,FALSE()),"") -> 3 | M12: =Aggregate!P8 -> Chase Brown | N12: =VLOOKUP(Table10[[#This Row],[NAME]],Aggregate!P:AA,4,FALSE()) -> CIN/6 | O12: =IFERROR(VLOOKUP(Table10[[#This Row],[NAME]],Aggregate!$P:$AA,8,FALSE()),"") -> 213.43189 | P12: =IF(Scoring!$K$6="Auction",IFERROR(VLOOKUP(Table10[[#This Row],[NAME]],Aggregate!$P:$AA,10,FALSE()),""),IFERROR(VLOOKUP(Table10[[#This Row],[NAME]],Aggregate!$P:$AA,9,FALSE()),"")) -> 85.88615 | Q12: =SUMIFS(T13:$T$84,S13:$S$84,"<>x",S13:$S$84,"<>o",T13:$T$84,">0")/Aggregate!$X$1 -> 0.51114673 | R12: =VLOOKUP(Table10[[#This Row],[NAME]],ECR!C:E,3,FALSE()) -> RB6 | T12: =VLOOKUP(M12,Aggregate!P:X,9,FALSE()) -> 85.88615 | V12: =IFERROR(VLOOKUP(Table11[[#This Row],[NAME]],Aggregate!$AD:$AO,11,FALSE()),"") -> 3 | W12: =Aggregate!AD9 -> A.J. Brown | X12: =VLOOKUP(Table11[[#This Row],[NAME]],Aggregate!AD:AO,4,FALSE()) -> NE/11 | Y12: =IFERROR(VLOOKUP(Table11[[#This Row],[NAME]],Aggregate!$AD:$AO,8,FALSE()),"") -> 188.45387 | Z12: =IF(Scoring!$K$6="Auction",IFERROR(VLOOKUP(Table11[[#This Row],[NAME]],Aggregate!$AD:$AO,10,FALSE()),""),IFERROR(VLOOKUP(Table11[[#This Row],[NAME]],Aggregate!$AD:$AO,9,FALSE()),"")) -> 62.775988 | AA12: =SUMIFS(AD13:$AD$84,AC13:$AC$84,"<>x",AC13:$AC$84,"<>o",AD13:$AD$84,">0")/Aggregate!$AL$1 -> 0.47645289 | AB12: =VLOOKUP(Table11[[#This Row],[NAME]],ECR!C:E,3,FALSE()) -> WR7 | AD12: =VLOOKUP(W12,Aggregate!AD:AL,9,FALSE()) -> 62.775988
B13: =IFERROR(VLOOKUP(Table9[[#This Row],[NAME]],Aggregate!$B:$M,11,FALSE()),"") -> 5 | C13: =Aggregate!B15 -> Jaxson Dart | D13: =VLOOKUP(Table9[[#This Row],[NAME]],Aggregate!B:M,4,FALSE()) -> NYG/8 | E13: =IFERROR(VLOOKUP(Table9[[#This Row],[NAME]],Aggregate!$B:$M,8,FALSE()),"") -> 269.87614 | F13: =IF(Scoring!$K$6="Auction",IFERROR(VLOOKUP(Table9[[#This Row],[NAME]],Aggregate!$B:$M,10,FALSE()),""),IFERROR(VLOOKUP(Table9[[#This Row],[NAME]],Aggregate!$B:$M,9,FALSE()),"")) -> 1.4967769 | G13: =SUMIFS(J14:$J$44,I14:$I$44,"<>x",I14:$I$44,"<>o",J14:$J$44,">0")/Aggregate!$J$1 -> 0.017566174 | H13: =VLOOKUP(Table9[[#This Row],[NAME]],ECR!C:E,3,FALSE()) -> QB13 | J13: =VLOOKUP(C13,Aggregate!B:J,9,FALSE()) -> 1.4967769 | L13: =IFERROR(VLOOKUP(Table10[[#This Row],[NAME]],Aggregate!$P:$AA,11,FALSE()),"") -> 3 | M13: =Aggregate!P9 -> Saquon Barkley | N13: =VLOOKUP(Table10[[#This Row],[NAME]],Aggregate!P:AA,4,FALSE()) -> PHI/10 | O13: =IFERROR(VLOOKUP(Table10[[#This Row],[NAME]],Aggregate!$P:$AA,8,FALSE()),"") -> 210.11738 | P13: =IF(Scoring!$K$6="Auction",IFERROR(VLOOKUP(Table10[[#This Row],[NAME]],Aggregate!$P:$AA,10,FALSE()),""),IFERROR(VLOOKUP(Table10[[#This Row],[NAME]],Aggregate!$P:$AA,9,FALSE()),"")) -> 82.571639 | Q13: =SUMIFS(T14:$T$84,S14:$S$84,"<>x",S14:$S$84,"<>o",T14:$T$84,">0")/Aggregate!$X$1 -> 0.46654514 | R13: =VLOOKUP(Table10[[#This Row],[NAME]],ECR!C:E,3,FALSE()) -> RB7 | T13: =VLOOKUP(M13,Aggregate!P:X,9,FALSE()) -> 82.571639 | V13: =IFERROR(VLOOKUP(Table11[[#This Row],[NAME]],Aggregate!$AD:$AO,11,FALSE()),"") -> 3 | W13: =Aggregate!AD13 -> Chris Olave | X13: =VLOOKUP(Table11[[#This Row],[NAME]],Aggregate!AD:AO,4,FALSE()) -> NO/8 | Y13: =IFERROR(VLOOKUP(Table11[[#This Row],[NAME]],Aggregate!$AD:$AO,8,FALSE()),"") -> 184.33494 | Z13: =IF(Scoring!$K$6="Auction",IFERROR(VLOOKUP(Table11[[#This Row],[NAME]],Aggregate!$AD:$AO,10,FALSE()),""),IFERROR(VLOOKUP(Table11[[#This Row],[NAME]],Aggregate!$AD:$AO,9,FALSE()),"")) -> 58.657057 | AA13: =SUMIFS(AD14:$AD$84,AC14:$AC$84,"<>x",AC14:$AC$84,"<>o",AD14:$AD$84,">0")/Aggregate!$AL$1 -> 0.4343756 | AB13: =VLOOKUP(Table11[[#This Row],[NAME]],ECR!C:E,3,FALSE()) -> WR11 | AD13: =VLOOKUP(W13,Aggregate!AD:AL,9,FALSE()) -> 58.657057
B14: =IFERROR(VLOOKUP(Table9[[#This Row],[NAME]],Aggregate!$B:$M,11,FALSE()),"") -> 5 | C14: =Aggregate!B13 -> Brock Purdy | D14: =VLOOKUP(Table9[[#This Row],[NAME]],Aggregate!B:M,4,FALSE()) -> SF/8 | E14: =IFERROR(VLOOKUP(Table9[[#This Row],[NAME]],Aggregate!$B:$M,8,FALSE()),"") -> 269.87395 | F14: =IF(Scoring!$K$6="Auction",IFERROR(VLOOKUP(Table9[[#This Row],[NAME]],Aggregate!$B:$M,10,FALSE()),""),IFERROR(VLOOKUP(Table9[[#This Row],[NAME]],Aggregate!$B:$M,9,FALSE()),"")) -> 1.4945889 | G14: =SUMIFS(J15:$J$44,I15:$I$44,"<>x",I15:$I$44,"<>o",J15:$J$44,">0")/Aggregate!$J$1 -> 0.0068105172 | H14: =VLOOKUP(Table9[[#This Row],[NAME]],ECR!C:E,3,FALSE()) -> QB11 | J14: =VLOOKUP(C14,Aggregate!B:J,9,FALSE()) -> 1.4945889 | L14: =IFERROR(VLOOKUP(Table10[[#This Row],[NAME]],Aggregate!$P:$AA,11,FALSE()),"") -> 3 | M14: =Aggregate!P11 -> Kenneth Walker III | N14: =VLOOKUP(Table10[[#This Row],[NAME]],Aggregate!P:AA,4,FALSE()) -> KC/5 | O14: =IFERROR(VLOOKUP(Table10[[#This Row],[NAME]],Aggregate!$P:$AA,8,FALSE()),"") -> 201.89785 | P14: =IF(Scoring!$K$6="Auction",IFERROR(VLOOKUP(Table10[[#This Row],[NAME]],Aggregate!$P:$AA,10,FALSE()),""),IFERROR(VLOOKUP(Table10[[#This Row],[NAME]],Aggregate!$P:$AA,9,FALSE()),"")) -> 74.352109 | Q14: =SUMIFS(T15:$T$84,S15:$S$84,"<>x",S15:$S$84,"<>o",T15:$T$84,">0")/Aggregate!$X$1 -> 0.42638338 | R14: =VLOOKUP(Table10[[#This Row],[NAME]],ECR!C:E,3,FALSE()) -> RB9 | T14: =VLOOKUP(M14,Aggregate!P:X,9,FALSE()) -> 74.352109 | V14: =IFERROR(VLOOKUP(Table11[[#This Row],[NAME]],Aggregate!$AD:$AO,11,FALSE()),"") -> 3 | W14: =Aggregate!AD12 -> George Pickens | X14: =VLOOKUP(Table11[[#This Row],[NAME]],Aggregate!AD:AO,4,FALSE()) -> DAL/14 | Y14: =IFERROR(VLOOKUP(Table11[[#This Row],[NAME]],Aggregate!$AD:$AO,8,FALSE()),"") -> 183.66791 | Z14: =IF(Scoring!$K$6="Auction",IFERROR(VLOOKUP(Table11[[#This Row],[NAME]],Aggregate!$AD:$AO,10,FALSE()),""),IFERROR(VLOOKUP(Table11[[#This Row],[NAME]],Aggregate!$AD:$AO,9,FALSE()),"")) -> 57.990028 | AA14: =SUMIFS(AD15:$AD$84,AC15:$AC$84,"<>x",AC15:$AC$84,"<>o",AD15:$AD$84,">0")/Aggregate!$AL$1 -> 0.39277679 | AB14: =VLOOKUP(Table11[[#This Row],[NAME]],ECR!C:E,3,FALSE()) -> WR10 | AD14: =VLOOKUP(W14,Aggregate!AD:AL,9,FALSE()) -> 57.990028
B15: =IFERROR(VLOOKUP(Table9[[#This Row],[NAME]],Aggregate!$B:$M,11,FALSE()),"") -> 5 | C15: =Aggregate!B9 -> Caleb Williams | D15: =VLOOKUP(Table9[[#This Row],[NAME]],Aggregate!B:M,4,FALSE()) -> CHI/10 | E15: =IFERROR(VLOOKUP(Table9[[#This Row],[NAME]],Aggregate!$B:$M,8,FALSE()),"") -> 269.32574 | F15: =IF(Scoring!$K$6="Auction",IFERROR(VLOOKUP(Table9[[#This Row],[NAME]],Aggregate!$B:$M,10,FALSE()),""),IFERROR(VLOOKUP(Table9[[#This Row],[NAME]],Aggregate!$B:$M,9,FALSE()),"")) -> 0.94637866 | G15: =SUMIFS(J16:$J$44,I16:$I$44,"<>x",I16:$I$44,"<>o",J16:$J$44,">0")/Aggregate!$J$1 -> 0 | H15: =VLOOKUP(Table9[[#This Row],[NAME]],ECR!C:E,3,FALSE()) -> QB7 | J15: =VLOOKUP(C15,Aggregate!B:J,9,FALSE()) -> 0.94637866 | L15: =IFERROR(VLOOKUP(Table10[[#This Row],[NAME]],Aggregate!$P:$AA,11,FALSE()),"") -> 4 | M15: =Aggregate!P14 -> Ashton Jeanty | N15: =VLOOKUP(Table10[[#This Row],[NAME]],Aggregate!P:AA,4,FALSE()) -> LV/13 | O15: =IFERROR(VLOOKUP(Table10[[#This Row],[NAME]],Aggregate!$P:$AA,8,FALSE()),"") -> 196.03024 | P15: =IF(Scoring!$K$6="Auction",IFERROR(VLOOKUP(Table10[[#This Row],[NAME]],Aggregate!$P:$AA,10,FALSE()),""),IFERROR(VLOOKUP(Table10[[#This Row],[NAME]],Aggregate!$P:$AA,9,FALSE()),"")) -> 68.484497 | Q15: =SUMIFS(T16:$T$84,S16:$S$84,"<>x",S16:$S$84,"<>o",T16:$T$84,">0")/Aggregate!$X$1 -> 0.38939105 | R15: =VLOOKUP(Table10[[#This Row],[NAME]],ECR!C:E,3,FALSE()) -> RB12 | T15: =VLOOKUP(M15,Aggregate!P:X,9,FALSE()) -> 68.484497 | V15: =IFERROR(VLOOKUP(Table11[[#This Row],[NAME]],Aggregate!$AD:$AO,11,FALSE()),"") -> 3 | W15: =Aggregate!AD11 -> Nico Collins | X15: =VLOOKUP(Table11[[#This Row],[NAME]],Aggregate!AD:AO,4,FALSE()) -> HOU/8 | Y15: =IFERROR(VLOOKUP(Table11[[#This Row],[NAME]],Aggregate!$AD:$AO,8,FALSE()),"") -> 182.92873 | Z15: =IF(Scoring!$K$6="Auction",IFERROR(VLOOKUP(Table11[[#This Row],[NAME]],Aggregate!$AD:$AO,10,FALSE()),""),IFERROR(VLOOKUP(Table11[[#This Row],[NAME]],Aggregate!$AD:$AO,9,FALSE()),"")) -> 57.250847 | AA15: =SUMIFS(AD16:$AD$84,AC16:$AC$84,"<>x",AC16:$AC$84,"<>o",AD16:$AD$84,">0")/Aggregate!$AL$1 -> 0.35170823 | AB15: =VLOOKUP(Table11[[#This Row],[NAME]],ECR!C:E,3,FALSE()) -> WR9 | AD15: =VLOOKUP(W15,Aggregate!AD:AL,9,FALSE()) -> 57.250847
B16: =IFERROR(VLOOKUP(Table9[[#This Row],[NAME]],Aggregate!$B:$M,11,FALSE()),"") -> 6 | C16: =Aggregate!B10 -> Justin Herbert | D16: =VLOOKUP(Table9[[#This Row],[NAME]],Aggregate!B:M,4,FALSE()) -> LAC/7 | E16: =IFERROR(VLOOKUP(Table9[[#This Row],[NAME]],Aggregate!$B:$M,8,FALSE()),"") -> 268.37937 | F16: =IF(Scoring!$K$6="Auction",IFERROR(VLOOKUP(Table9[[#This Row],[NAME]],Aggregate!$B:$M,10,FALSE()),""),IFERROR(VLOOKUP(Table9[[#This Row],[NAME]],Aggregate!$B:$M,9,FALSE()),"")) -> 0 | G16: =SUMIFS(J17:$J$44,I17:$I$44,"<>x",I17:$I$44,"<>o",J17:$J$44,">0")/Aggregate!$J$1 -> 0 | H16: =VLOOKUP(Table9[[#This Row],[NAME]],ECR!C:E,3,FALSE()) -> QB8 | J16: =VLOOKUP(C16,Aggregate!B:J,9,FALSE()) -> 0 | L16: =IFERROR(VLOOKUP(Table10[[#This Row],[NAME]],Aggregate!$P:$AA,11,FALSE()),"") -> 4 | M16: =Aggregate!P12 -> Omarion Hampton | N16: =VLOOKUP(Table10[[#This Row],[NAME]],Aggregate!P:AA,4,FALSE()) -> LAC/7 | O16: =IFERROR(VLOOKUP(Table10[[#This Row],[NAME]],Aggregate!$P:$AA,8,FALSE()),"") -> 195.37082 | P16: =IF(Scoring!$K$6="Auction",IFERROR(VLOOKUP(Table10[[#This Row],[NAME]],Aggregate!$P:$AA,10,FALSE()),""),IFERROR(VLOOKUP(Table10[[#This Row],[NAME]],Aggregate!$P:$AA,9,FALSE()),"")) -> 67.82508 | Q16: =SUMIFS(T17:$T$84,S17:$S$84,"<>x",S17:$S$84,"<>o",T17:$T$84,">0")/Aggregate!$X$1 -> 0.3527549 | R16: =VLOOKUP(Table10[[#This Row],[NAME]],ECR!C:E,3,FALSE()) -> RB10 | T16: =VLOOKUP(M16,Aggregate!P:X,9,FALSE()) -> 67.82508 | V16: =IFERROR(VLOOKUP(Table11[[#This Row],[NAME]],Aggregate!$AD:$AO,11,FALSE()),"") -> 3 | W16: =Aggregate!AD16 -> Rashee Rice | X16: =VLOOKUP(Table11[[#This Row],[NAME]],Aggregate!AD:AO,4,FALSE()) -> KC/5 | Y16: =IFERROR(VLOOKUP(Table11[[#This Row],[NAME]],Aggregate!$AD:$AO,8,FALSE()),"") -> 180.80471 | Z16: =IF(Scoring!$K$6="Auction",IFERROR(VLOOKUP(Table11[[#This Row],[NAME]],Aggregate!$AD:$AO,10,FALSE()),""),IFERROR(VLOOKUP(Table11[[#This Row],[NAME]],Aggregate!$AD:$AO,9,FALSE()),"")) -> 55.126827 | AA16: =SUMIFS(AD17:$AD$84,AC17:$AC$84,"<>x",AC17:$AC$84,"<>o",AD17:$AD$84,">0")/Aggregate!$AL$1 -> 0.31216333 | AB16: =VLOOKUP(Table11[[#This Row],[NAME]],ECR!C:E,3,FALSE()) -> WR14 | AD16: =VLOOKUP(W16,Aggregate!AD:AL,9,FALSE()) -> 55.126827
B17: =IFERROR(VLOOKUP(Table9[[#This Row],[NAME]],Aggregate!$B:$M,11,FALSE()),"") -> 7 | C17: =Aggregate!B16 -> Patrick Mahomes II | D17: =VLOOKUP(Table9[[#This Row],[NAME]],Aggregate!B:M,4,FALSE()) -> KC/5 | E17: =IFERROR(VLOOKUP(Table9[[#This Row],[NAME]],Aggregate!$B:$M,8,FALSE()),"") -> 264.65785 | F17: =IF(Scoring!$K$6="Auction",IFERROR(VLOOKUP(Table9[[#This Row],[NAME]],Aggregate!$B:$M,10,FALSE()),""),IFERROR(VLOOKUP(Table9[[#This Row],[NAME]],Aggregate!$B:$M,9,FALSE()),"")) -> -3.7215181 | G17: =SUMIFS(J18:$J$44,I18:$I$44,"<>x",I18:$I$44,"<>o",J18:$J$44,">0")/Aggregate!$J$1 -> 0 | H17: =VLOOKUP(Table9[[#This Row],[NAME]],ECR!C:E,3,FALSE()) -> QB14 | J17: =VLOOKUP(C17,Aggregate!B:J,9,FALSE()) -> -3.7215181 | L17: =IFERROR(VLOOKUP(Table10[[#This Row],[NAME]],Aggregate!$P:$AA,11,FALSE()),"") -> 4 | M17: =Aggregate!P18 -> Jeremiyah Love | N17: =VLOOKUP(Table10[[#This Row],[NAME]],Aggregate!P:AA,4,FALSE()) -> ARI/14 | O17: =IFERROR(VLOOKUP(Table10[[#This Row],[NAME]],Aggregate!$P:$AA,8,FALSE()),"") -> 191.58899 | P17: =IF(Scoring!$K$6="Auction",IFERROR(VLOOKUP(Table10[[#This Row],[NAME]],Aggregate!$P:$AA,10,FALSE()),""),IFERROR(VLOOKUP(Table10[[#This Row],[NAME]],Aggregate!$P:$AA,9,FALSE()),"")) -> 64.043251 | Q17: =SUMIFS(T18:$T$84,S18:$S$84,"<>x",S18:$S$84,"<>o",T18:$T$84,">0")/Aggregate!$X$1 -> 0.31816154 | R17: =VLOOKUP(Table10[[#This Row],[NAME]],ECR!C:E,3,FALSE()) -> RB16 | T17: =VLOOKUP(M17,Aggregate!P:X,9,FALSE()) -> 64.043251 | V17: =IFERROR(VLOOKUP(Table11[[#This Row],[NAME]],Aggregate!$AD:$AO,11,FALSE()),"") -> 4 | W17: =Aggregate!AD14 -> Malik Nabers | X17: =VLOOKUP(Table11[[#This Row],[NAME]],Aggregate!AD:AO,4,FALSE()) -> NYG/8 | Y17: =IFERROR(VLOOKUP(Table11[[#This Row],[NAME]],Aggregate!$AD:$AO,8,FALSE()),"") -> 174.92057 | Z17: =IF(Scoring!$K$6="Auction",IFERROR(VLOOKUP(Table11[[#This Row],[NAME]],Aggregate!$AD:$AO,10,FALSE()),""),IFERROR(VLOOKUP(Table11[[#This Row],[NAME]],Aggregate!$AD:$AO,9,FALSE()),"")) -> 49.242689 | AA17: =SUMIFS(AD18:$AD$84,AC18:$AC$84,"<>x",AC18:$AC$84,"<>o",AD18:$AD$84,">0")/Aggregate!$AL$1 -> 0.27683938 | AB17: =VLOOKUP(Table11[[#This Row],[NAME]],ECR!C:E,3,FALSE()) -> WR12 | AD17: =VLOOKUP(W17,Aggregate!AD:AL,9,FALSE()) -> 49.242689
B18: =IFERROR(VLOOKUP(Table9[[#This Row],[NAME]],Aggregate!$B:$M,11,FALSE()),"") -> 7 | C18: =Aggregate!B14 -> Bo Nix | D18: =VLOOKUP(Table9[[#This Row],[NAME]],Aggregate!B:M,4,FALSE()) -> DEN/10 | E18: =IFERROR(VLOOKUP(Table9[[#This Row],[NAME]],Aggregate!$B:$M,8,FALSE()),"") -> 262.33128 | F18: =IF(Scoring!$K$6="Auction",IFERROR(VLOOKUP(Table9[[#This Row],[NAME]],Aggregate!$B:$M,10,FALSE()),""),IFERROR(VLOOKUP(Table9[[#This Row],[NAME]],Aggregate!$B:$M,9,FALSE()),"")) -> -6.0480811 | G18: =SUMIFS(J19:$J$44,I19:$I$44,"<>x",I19:$I$44,"<>o",J19:$J$44,">0")/Aggregate!$J$1 -> 0 | H18: =VLOOKUP(Table9[[#This Row],[NAME]],ECR!C:E,3,FALSE()) -> QB12 | J18: =VLOOKUP(C18,Aggregate!B:J,9,FALSE()) -> -6.0480811 | L18: =IFERROR(VLOOKUP(Table10[[#This Row],[NAME]],Aggregate!$P:$AA,11,FALSE()),"") -> 4 | M18: =Aggregate!P16 -> Javonte Williams | N18: =VLOOKUP(Table10[[#This Row],[NAME]],Aggregate!P:AA,4,FALSE()) -> DAL/14 | O18: =IFERROR(VLOOKUP(Table10[[#This Row],[NAME]],Aggregate!$P:$AA,8,FALSE()),"") -> 188.87935 | P18: =IF(Scoring!$K$6="Auction",IFERROR(VLOOKUP(Table10[[#This Row],[NAME]],Aggregate!$P:$AA,10,FALSE()),""),IFERROR(VLOOKUP(Table10[[#This Row],[NAME]],Aggregate!$P:$AA,9,FALSE()),"")) -> 61.33361 | Q18: =SUMIFS(T19:$T$84,S19:$S$84,"<>x",S19:$S$84,"<>o",T19:$T$84,">0")/Aggregate!$X$1 -> 0.28503181 | R18: =VLOOKUP(Table10[[#This Row],[NAME]],ECR!C:E,3,FALSE()) -> RB14 | T18: =VLOOKUP(M18,Aggregate!P:X,9,FALSE()) -> 61.33361 | V18: =IFERROR(VLOOKUP(Table11[[#This Row],[NAME]],Aggregate!$AD:$AO,11,FALSE()),"") -> 4 | W18: =Aggregate!AD17 -> Zay Flowers | X18: =VLOOKUP(Table11[[#This Row],[NAME]],Aggregate!AD:AO,4,FALSE()) -> BAL/13 | Y18: =IFERROR(VLOOKUP(Table11[[#This Row],[NAME]],Aggregate!$AD:$AO,8,FALSE()),"") -> 167.44822 | Z18: =IF(Scoring!$K$6="Auction",IFERROR(VLOOKUP(Table11[[#This Row],[NAME]],Aggregate!$AD:$AO,10,FALSE()),""),IFERROR(VLOOKUP(Table11[[#This Row],[NAME]],Aggregate!$AD:$AO,9,FALSE()),"")) -> 41.770337 | AA18: =SUMIFS(AD19:$AD$84,AC19:$AC$84,"<>x",AC19:$AC$84,"<>o",AD19:$AD$84,">0")/Aggregate!$AL$1 -> 0.24687567 | AB18: =VLOOKUP(Table11[[#This Row],[NAME]],ECR!C:E,3,FALSE()) -> WR15 | AD18: =VLOOKUP(W18,Aggregate!AD:AL,9,FALSE()) -> 41.770337
B19: =IFERROR(VLOOKUP(Table9[[#This Row],[NAME]],Aggregate!$B:$M,11,FALSE()),"") -> 8 | C19: =Aggregate!B18 -> Matthew Stafford | D19: =VLOOKUP(Table9[[#This Row],[NAME]],Aggregate!B:M,4,FALSE()) -> LAR/11 | E19: =IFERROR(VLOOKUP(Table9[[#This Row],[NAME]],Aggregate!$B:$M,8,FALSE()),"") -> 252.56179 | F19: =IF(Scoring!$K$6="Auction",IFERROR(VLOOKUP(Table9[[#This Row],[NAME]],Aggregate!$B:$M,10,FALSE()),""),IFERROR(VLOOKUP(Table9[[#This Row],[NAME]],Aggregate!$B:$M,9,FALSE()),"")) -> -15.817578 | G19: =SUMIFS(J20:$J$44,I20:$I$44,"<>x",I20:$I$44,"<>o",J20:$J$44,">0")/Aggregate!$J$1 -> 0 | H19: =VLOOKUP(Table9[[#This Row],[NAME]],ECR!C:E,3,FALSE()) -> QB16 | J19: =VLOOKUP(C19,Aggregate!B:J,9,FALSE()) -> -15.817578 | L19: =IFERROR(VLOOKUP(Table10[[#This Row],[NAME]],Aggregate!$P:$AA,11,FALSE()),"") -> 4 | M19: =Aggregate!P15 -> Kyren Williams | N19: =VLOOKUP(Table10[[#This Row],[NAME]],Aggregate!P:AA,4,FALSE()) -> LAR/11 | O19: =IFERROR(VLOOKUP(Table10[[#This Row],[NAME]],Aggregate!$P:$AA,8,FALSE()),"") -> 188.28482 | P19: =IF(Scoring!$K$6="Auction",IFERROR(VLOOKUP(Table10[[#This Row],[NAME]],Aggregate!$P:$AA,10,FALSE()),""),IFERROR(VLOOKUP(Table10[[#This Row],[NAME]],Aggregate!$P:$AA,9,FALSE()),"")) -> 60.739083 | Q19: =SUMIFS(T20:$T$84,S20:$S$84,"<>x",S20:$S$84,"<>o",T20:$T$84,">0")/Aggregate!$X$1 -> 0.25222321 | R19: =VLOOKUP(Table10[[#This Row],[NAME]],ECR!C:E,3,FALSE()) -> RB13 | T19: =VLOOKUP(M19,Aggregate!P:X,9,FALSE()) -> 60.739083 | V19: =IFERROR(VLOOKUP(Table11[[#This Row],[NAME]],Aggregate!$AD:$AO,11,FALSE()),"") -> 4 | W19: =Aggregate!AD15 -> DeVonta Smith | X19: =VLOOKUP(Table11[[#This Row],[NAME]],Aggregate!AD:AO,4,FALSE()) -> PHI/10 | Y19: =IFERROR(VLOOKUP(Table11[[#This Row],[NAME]],Aggregate!$AD:$AO,8,FALSE()),"") -> 165.73653 | Z19: =IF(Scoring!$K$6="Auction",IFERROR(VLOOKUP(Table11[[#This Row],[NAME]],Aggregate!$AD:$AO,10,FALSE()),""),IFERROR(VLOOKUP(Table11[[#This Row],[NAME]],Aggregate!$AD:$AO,9,FALSE()),"")) -> 40.058654 | AA19: =SUMIFS(AD20:$AD$84,AC20:$AC$84,"<>x",AC20:$AC$84,"<>o",AD20:$AD$84,">0")/Aggregate!$AL$1 -> 0.21813983 | AB19: =VLOOKUP(Table11[[#This Row],[NAME]],ECR!C:E,3,FALSE()) -> WR13 | AD19: =VLOOKUP(W19,Aggregate!AD:AL,9,FALSE()) -> 40.058654
B20: =IFERROR(VLOOKUP(Table9[[#This Row],[NAME]],Aggregate!$B:$M,11,FALSE()),"") -> 8 | C20: =Aggregate!B17 -> Jared Goff | D20: =VLOOKUP(Table9[[#This Row],[NAME]],Aggregate!B:M,4,FALSE()) -> DET/6 | E20: =IFERROR(VLOOKUP(Table9[[#This Row],[NAME]],Aggregate!$B:$M,8,FALSE()),"") -> 251.81997 | F20: =IF(Scoring!$K$6="Auction",IFERROR(VLOOKUP(Table9[[#This Row],[NAME]],Aggregate!$B:$M,10,FALSE()),""),IFERROR(VLOOKUP(Table9[[#This Row],[NAME]],Aggregate!$B:$M,9,FALSE()),"")) -> -16.559392 | G20: =SUMIFS(J21:$J$44,I21:$I$44,"<>x",I21:$I$44,"<>o",J21:$J$44,">0")/Aggregate!$J$1 -> 0 | H20: =VLOOKUP(Table9[[#This Row],[NAME]],ECR!C:E,3,FALSE()) -> QB15 | J20: =VLOOKUP(C20,Aggregate!B:J,9,FALSE()) -> -16.559392 | L20: =IFERROR(VLOOKUP(Table10[[#This Row],[NAME]],Aggregate!$P:$AA,11,FALSE()),"") -> 4 | M20: =Aggregate!P17 -> Breece Hall | N20: =VLOOKUP(Table10[[#This Row],[NAME]],Aggregate!P:AA,4,FALSE()) -> NYJ/13 | O20: =IFERROR(VLOOKUP(Table10[[#This Row],[NAME]],Aggregate!$P:$AA,8,FALSE()),"") -> 187.19772 | P20: =IF(Scoring!$K$6="Auction",IFERROR(VLOOKUP(Table10[[#This Row],[NAME]],Aggregate!$P:$AA,10,FALSE()),""),IFERROR(VLOOKUP(Table10[[#This Row],[NAME]],Aggregate!$P:$AA,9,FALSE()),"")) -> 59.651982 | Q20: =SUMIFS(T21:$T$84,S21:$S$84,"<>x",S21:$S$84,"<>o",T21:$T$84,">0")/Aggregate!$X$1 -> 0.22000182 | R20: =VLOOKUP(Table10[[#This Row],[NAME]],ECR!C:E,3,FALSE()) -> RB15 | T20: =VLOOKUP(M20,Aggregate!P:X,9,FALSE()) -> 59.651982 | V20: =IFERROR(VLOOKUP(Table11[[#This Row],[NAME]],Aggregate!$AD:$AO,11,FALSE()),"") -> 4 | W20: =Aggregate!AD21 -> Garrett Wilson | X20: =VLOOKUP(Table11[[#This Row],[NAME]],Aggregate!AD:AO,4,FALSE()) -> NYJ/13 | Y20: =IFERROR(VLOOKUP(Table11[[#This Row],[NAME]],Aggregate!$AD:$AO,8,FALSE()),"") -> 159.2144 | Z20: =IF(Scoring!$K$6="Auction",IFERROR(VLOOKUP(Table11[[#This Row],[NAME]],Aggregate!$AD:$AO,10,FALSE()),""),IFERROR(VLOOKUP(Table11[[#This Row],[NAME]],Aggregate!$AD:$AO,9,FALSE()),"")) -> 33.536519 | AA20: =SUMIFS(AD21:$AD$84,AC21:$AC$84,"<>x",AC21:$AC$84,"<>o",AD21:$AD$84,">0")/Aggregate!$AL$1 -> 0.19408261 | AB20: =VLOOKUP(Table11[[#This Row],[NAME]],ECR!C:E,3,FALSE()) -> WR19 | AD20: =VLOOKUP(W20,Aggregate!AD:AL,9,FALSE()) -> 33.536519
B21: =IFERROR(VLOOKUP(Table9[[#This Row],[NAME]],Aggregate!$B:$M,11,FALSE()),"") -> 8 | C21: =Aggregate!B19 -> Kyler Murray | D21: =VLOOKUP(Table9[[#This Row],[NAME]],Aggregate!B:M,4,FALSE()) -> MIN/6 | E21: =IFERROR(VLOOKUP(Table9[[#This Row],[NAME]],Aggregate!$B:$M,8,FALSE()),"") -> 250.55691 | F21: =IF(Scoring!$K$6="Auction",IFERROR(VLOOKUP(Table9[[#This Row],[NAME]],Aggregate!$B:$M,10,FALSE()),""),IFERROR(VLOOKUP(Table9[[#This Row],[NAME]],Aggregate!$B:$M,9,FALSE()),"")) -> -17.822452 | G21: =SUMIFS(J22:$J$44,I22:$I$44,"<>x",I22:$I$44,"<>o",J22:$J$44,">0")/Aggregate!$J$1 -> 0 | H21: =VLOOKUP(Table9[[#This Row],[NAME]],ECR!C:E,3,FALSE()) -> QB17 | J21: =VLOOKUP(C21,Aggregate!B:J,9,FALSE()) -> -17.822452 | L21: =IFERROR(VLOOKUP(Table10[[#This Row],[NAME]],Aggregate!$P:$AA,11,FALSE()),"") -> 4 | M21: =Aggregate!P19 -> Travis Etienne Jr. | N21: =VLOOKUP(Table10[[#This Row],[NAME]],Aggregate!P:AA,4,FALSE()) -> NO/8 | O21: =IFERROR(VLOOKUP(Table10[[#This Row],[NAME]],Aggregate!$P:$AA,8,FALSE()),"") -> 181.29835 | P21: =IF(Scoring!$K$6="Auction",IFERROR(VLOOKUP(Table10[[#This Row],[NAME]],Aggregate!$P:$AA,10,FALSE()),""),IFERROR(VLOOKUP(Table10[[#This Row],[NAME]],Aggregate!$P:$AA,9,FALSE()),"")) -> 53.752614 | Q21: =SUMIFS(T22:$T$84,S22:$S$84,"<>x",S22:$S$84,"<>o",T22:$T$84,">0")/Aggregate!$X$1 -> 0.190967 | R21: =VLOOKUP(Table10[[#This Row],[NAME]],ECR!C:E,3,FALSE()) -> RB17 | T21: =VLOOKUP(M21,Aggregate!P:X,9,FALSE()) -> 53.752614 | V21: =IFERROR(VLOOKUP(Table11[[#This Row],[NAME]],Aggregate!$AD:$AO,11,FALSE()),"") -> 4 | W21: =Aggregate!AD18 -> Tee Higgins | X21: =VLOOKUP(Table11[[#This Row],[NAME]],Aggregate!AD:AO,4,FALSE()) -> CIN/6 | Y21: =IFERROR(VLOOKUP(Table11[[#This Row],[NAME]],Aggregate!$AD:$AO,8,FALSE()),"") -> 158.12437 | Z21: =IF(Scoring!$K$6="Auction",IFERROR(VLOOKUP(Table11[[#This Row],[NAME]],Aggregate!$AD:$AO,10,FALSE()),""),IFERROR(VLOOKUP(Table11[[#This Row],[NAME]],Aggregate!$AD:$AO,9,FALSE()),"")) -> 32.446492 | AA21: =SUMIFS(AD22:$AD$84,AC22:$AC$84,"<>x",AC22:$AC$84,"<>o",AD22:$AD$84,">0")/Aggregate!$AL$1 -> 0.17080731 | AB21: =VLOOKUP(Table11[[#This Row],[NAME]],ECR!C:E,3,FALSE()) -> WR16 | AD21: =VLOOKUP(W21,Aggregate!AD:AL,9,FALSE()) -> 32.446492
B22: =IFERROR(VLOOKUP(Table9[[#This Row],[NAME]],Aggregate!$B:$M,11,FALSE()),"") -> 9 | C22: =Aggregate!B21 -> Baker Mayfield | D22: =VLOOKUP(Table9[[#This Row],[NAME]],Aggregate!B:M,4,FALSE()) -> TB/10 | E22: =IFERROR(VLOOKUP(Table9[[#This Row],[NAME]],Aggregate!$B:$M,8,FALSE()),"") -> 238.99228 | F22: =IF(Scoring!$K$6="Auction",IFERROR(VLOOKUP(Table9[[#This Row],[NAME]],Aggregate!$B:$M,10,FALSE()),""),IFERROR(VLOOKUP(Table9[[#This Row],[NAME]],Aggregate!$B:$M,9,FALSE()),"")) -> -29.387087 | G22: =SUMIFS(J23:$J$44,I23:$I$44,"<>x",I23:$I$44,"<>o",J23:$J$44,">0")/Aggregate!$J$1 -> 0 | H22: =VLOOKUP(Table9[[#This Row],[NAME]],ECR!C:E,3,FALSE()) -> QB19 | J22: =VLOOKUP(C22,Aggregate!B:J,9,FALSE()) -> -29.387087 | L22: =IFERROR(VLOOKUP(Table10[[#This Row],[NAME]],Aggregate!$P:$AA,11,FALSE()),"") -> 4 | M22: =Aggregate!P22 -> Cam Skattebo | N22: =VLOOKUP(Table10[[#This Row],[NAME]],Aggregate!P:AA,4,FALSE()) -> NYG/8 | O22: =IFERROR(VLOOKUP(Table10[[#This Row],[NAME]],Aggregate!$P:$AA,8,FALSE()),"") -> 175.00966 | P22: =IF(Scoring!$K$6="Auction",IFERROR(VLOOKUP(Table10[[#This Row],[NAME]],Aggregate!$P:$AA,10,FALSE()),""),IFERROR(VLOOKUP(Table10[[#This Row],[NAME]],Aggregate!$P:$AA,9,FALSE()),"")) -> 47.463921 | Q22: =SUMIFS(T23:$T$84,S23:$S$84,"<>x",S23:$S$84,"<>o",T23:$T$84,">0")/Aggregate!$X$1 -> 0.16532907 | R22: =VLOOKUP(Table10[[#This Row],[NAME]],ECR!C:E,3,FALSE()) -> RB20 | T22: =VLOOKUP(M22,Aggregate!P:X,9,FALSE()) -> 47.463921 | V22: =IFERROR(VLOOKUP(Table11[[#This Row],[NAME]],Aggregate!$AD:$AO,11,FALSE()),"") -> 4 | W22: =Aggregate!AD22 -> Tetairoa McMillan | X22: =VLOOKUP(Table11[[#This Row],[NAME]],Aggregate!AD:AO,4,FALSE()) -> CAR/5 | Y22: =IFERROR(VLOOKUP(Table11[[#This Row],[NAME]],Aggregate!$AD:$AO,8,FALSE()),"") -> 157.05231 | Z22: =IF(Scoring!$K$6="Auction",IFERROR(VLOOKUP(Table11[[#This Row],[NAME]],Aggregate!$AD:$AO,10,FALSE()),""),IFERROR(VLOOKUP(Table11[[#This Row],[NAME]],Aggregate!$AD:$AO,9,FALSE()),"")) -> 31.374431 | AA22: =SUMIFS(AD23:$AD$84,AC23:$AC$84,"<>x",AC23:$AC$84,"<>o",AD23:$AD$84,">0")/Aggregate!$AL$1 -> 0.14830105 | AB22: =VLOOKUP(Table11[[#This Row],[NAME]],ECR!C:E,3,FALSE()) -> WR20 | AD22: =VLOOKUP(W22,Aggregate!AD:AL,9,FALSE()) -> 31.374431
B23: =IFERROR(VLOOKUP(Table9[[#This Row],[NAME]],Aggregate!$B:$M,11,FALSE()),"") -> 9 | C23: =Aggregate!B22 -> Tyler Shough | D23: =VLOOKUP(Table9[[#This Row],[NAME]],Aggregate!B:M,4,FALSE()) -> NO/8 | E23: =IFERROR(VLOOKUP(Table9[[#This Row],[NAME]],Aggregate!$B:$M,8,FALSE()),"") -> 237.57109 | F23: =IF(Scoring!$K$6="Auction",IFERROR(VLOOKUP(Table9[[#This Row],[NAME]],Aggregate!$B:$M,10,FALSE()),""),IFERROR(VLOOKUP(Table9[[#This Row],[NAME]],Aggregate!$B:$M,9,FALSE()),"")) -> -30.808274 | G23: =SUMIFS(J24:$J$44,I24:$I$44,"<>x",I24:$I$44,"<>o",J24:$J$44,">0")/Aggregate!$J$1 -> 0 | H23: =VLOOKUP(Table9[[#This Row],[NAME]],ECR!C:E,3,FALSE()) -> QB20 | J23: =VLOOKUP(C23,Aggregate!B:J,9,FALSE()) -> -30.808274 | L23: =IFERROR(VLOOKUP(Table10[[#This Row],[NAME]],Aggregate!$P:$AA,11,FALSE()),"") -> 5 | M23: =Aggregate!P20 -> D'Andre Swift | N23: =VLOOKUP(Table10[[#This Row],[NAME]],Aggregate!P:AA,4,FALSE()) -> CHI/10 | O23: =IFERROR(VLOOKUP(Table10[[#This Row],[NAME]],Aggregate!$P:$AA,8,FALSE()),"") -> 174.37801 | P23: =IF(Scoring!$K$6="Auction",IFERROR(VLOOKUP(Table10[[#This Row],[NAME]],Aggregate!$P:$AA,10,FALSE()),""),IFERROR(VLOOKUP(Table10[[#This Row],[NAME]],Aggregate!$P:$AA,9,FALSE()),"")) -> 46.832275 | Q23: =SUMIFS(T24:$T$84,S24:$S$84,"<>x",S24:$S$84,"<>o",T24:$T$84,">0")/Aggregate!$X$1 -> 0.14003232 | R23: =VLOOKUP(Table10[[#This Row],[NAME]],ECR!C:E,3,FALSE()) -> RB18 | T23: =VLOOKUP(M23,Aggregate!P:X,9,FALSE()) -> 46.832275 | V23: =IFERROR(VLOOKUP(Table11[[#This Row],[NAME]],Aggregate!$AD:$AO,11,FALSE()),"") -> 5 | W23: =Aggregate!AD23 -> Emeka Egbuka | X23: =VLOOKUP(Table11[[#This Row],[NAME]],Aggregate!AD:AO,4,FALSE()) -> TB/10 | Y23: =IFERROR(VLOOKUP(Table11[[#This Row],[NAME]],Aggregate!$AD:$AO,8,FALSE()),"") -> 154.47706 | Z23: =IF(Scoring!$K$6="Auction",IFERROR(VLOOKUP(Table11[[#This Row],[NAME]],Aggregate!$AD:$AO,10,FALSE()),""),IFERROR(VLOOKUP(Table11[[#This Row],[NAME]],Aggregate!$AD:$AO,9,FALSE()),"")) -> 28.799183 | AA23: =SUMIFS(AD24:$AD$84,AC24:$AC$84,"<>x",AC24:$AC$84,"<>o",AD24:$AD$84,">0")/Aggregate!$AL$1 -> 0.12764212 | AB23: =VLOOKUP(Table11[[#This Row],[NAME]],ECR!C:E,3,FALSE()) -> WR21 | AD23: =VLOOKUP(W23,Aggregate!AD:AL,9,FALSE()) -> 28.799183
B24: =IFERROR(VLOOKUP(Table9[[#This Row],[NAME]],Aggregate!$B:$M,11,FALSE()),"") -> 9 | C24: =Aggregate!B20 -> Jordan Love | D24: =VLOOKUP(Table9[[#This Row],[NAME]],Aggregate!B:M,4,FALSE()) -> GB/11 | E24: =IFERROR(VLOOKUP(Table9[[#This Row],[NAME]],Aggregate!$B:$M,8,FALSE()),"") -> 235.88159 | F24: =IF(Scoring!$K$6="Auction",IFERROR(VLOOKUP(Table9[[#This Row],[NAME]],Aggregate!$B:$M,10,FALSE()),""),IFERROR(VLOOKUP(Table9[[#This Row],[NAME]],Aggregate!$B:$M,9,FALSE()),"")) -> -32.497775 | G24: =SUMIFS(J25:$J$44,I25:$I$44,"<>x",I25:$I$44,"<>o",J25:$J$44,">0")/Aggregate!$J$1 -> 0 | H24: =VLOOKUP(Table9[[#This Row],[NAME]],ECR!C:E,3,FALSE()) -> QB18 | J24: =VLOOKUP(C24,Aggregate!B:J,9,FALSE()) -> -32.497775 | L24: =IFERROR(VLOOKUP(Table10[[#This Row],[NAME]],Aggregate!$P:$AA,11,FALSE()),"") -> 5 | M24: =Aggregate!P21 -> Bucky Irving | N24: =VLOOKUP(Table10[[#This Row],[NAME]],Aggregate!P:AA,4,FALSE()) -> TB/10 | O24: =IFERROR(VLOOKUP(Table10[[#This Row],[NAME]],Aggregate!$P:$AA,8,FALSE()),"") -> 169.99665 | P24: =IF(Scoring!$K$6="Auction",IFERROR(VLOOKUP(Table10[[#This Row],[NAME]],Aggregate!$P:$AA,10,FALSE()),""),IFERROR(VLOOKUP(Table10[[#This Row],[NAME]],Aggregate!$P:$AA,9,FALSE()),"")) -> 42.450915 | Q24: =SUMIFS(T25:$T$84,S25:$S$84,"<>x",S25:$S$84,"<>o",T25:$T$84,">0")/Aggregate!$X$1 -> 0.11710219 | R24: =VLOOKUP(Table10[[#This Row],[NAME]],ECR!C:E,3,FALSE()) -> RB19 | T24: =VLOOKUP(M24,Aggregate!P:X,9,FALSE()) -> 42.450915 | V24: =IFERROR(VLOOKUP(Table11[[#This Row],[NAME]],Aggregate!$AD:$AO,11,FALSE()),"") -> 5 | W24: =Aggregate!AD20 -> Ladd McConkey | X24: =VLOOKUP(Table11[[#This Row],[NAME]],Aggregate!AD:AO,4,FALSE()) -> LAC/7 | Y24: =IFERROR(VLOOKUP(Table11[[#This Row],[NAME]],Aggregate!$AD:$AO,8,FALSE()),"") -> 150.91398 | Z24: =IF(Scoring!$K$6="Auction",IFERROR(VLOOKUP(Table11[[#This Row],[NAME]],Aggregate!$AD:$AO,10,FALSE()),""),IFERROR(VLOOKUP(Table11[[#This Row],[NAME]],Aggregate!$AD:$AO,9,FALSE()),"")) -> 25.236104 | AA24: =SUMIFS(AD25:$AD$84,AC25:$AC$84,"<>x",AC25:$AC$84,"<>o",AD25:$AD$84,">0")/Aggregate!$AL$1 -> 0.10953915 | AB24: =VLOOKUP(Table11[[#This Row],[NAME]],ECR!C:E,3,FALSE()) -> WR18 | AD24: =VLOOKUP(W24,Aggregate!AD:AL,9,FALSE()) -> 25.236104
B25: =IFERROR(VLOOKUP(Table9[[#This Row],[NAME]],Aggregate!$B:$M,11,FALSE()),"") -> 10 | C25: =Aggregate!B23 -> Malik Willis | D25: =VLOOKUP(Table9[[#This Row],[NAME]],Aggregate!B:M,4,FALSE()) -> MIA/6 | E25: =IFERROR(VLOOKUP(Table9[[#This Row],[NAME]],Aggregate!$B:$M,8,FALSE()),"") -> 226.15984 | F25: =IF(Scoring!$K$6="Auction",IFERROR(VLOOKUP(Table9[[#This Row],[NAME]],Aggregate!$B:$M,10,FALSE()),""),IFERROR(VLOOKUP(Table9[[#This Row],[NAME]],Aggregate!$B:$M,9,FALSE()),"")) -> -42.219526 | G25: =SUMIFS(J26:$J$44,I26:$I$44,"<>x",I26:$I$44,"<>o",J26:$J$44,">0")/Aggregate!$J$1 -> 0 | H25: =VLOOKUP(Table9[[#This Row],[NAME]],ECR!C:E,3,FALSE()) -> QB21 | J25: =VLOOKUP(C25,Aggregate!B:J,9,FALSE()) -> -42.219526 | L25: =IFERROR(VLOOKUP(Table10[[#This Row],[NAME]],Aggregate!$P:$AA,11,FALSE()),"") -> 5 | M25: =Aggregate!P24 -> Quinshon Judkins | N25: =VLOOKUP(Table10[[#This Row],[NAME]],Aggregate!P:AA,4,FALSE()) -> CLE/11 | O25: =IFERROR(VLOOKUP(Table10[[#This Row],[NAME]],Aggregate!$P:$AA,8,FALSE()),"") -> 166.43142 | P25: =IF(Scoring!$K$6="Auction",IFERROR(VLOOKUP(Table10[[#This Row],[NAME]],Aggregate!$P:$AA,10,FALSE()),""),IFERROR(VLOOKUP(Table10[[#This Row],[NAME]],Aggregate!$P:$AA,9,FALSE()),"")) -> 38.885682 | Q25: =SUMIFS(T26:$T$84,S26:$S$84,"<>x",S26:$S$84,"<>o",T26:$T$84,">0")/Aggregate!$X$1 -> 0.09609785 | R25: =VLOOKUP(Table10[[#This Row],[NAME]],ECR!C:E,3,FALSE()) -> RB22 | T25: =VLOOKUP(M25,Aggregate!P:X,9,FALSE()) -> 38.885682 | V25: =IFERROR(VLOOKUP(Table11[[#This Row],[NAME]],Aggregate!$AD:$AO,11,FALSE()),"") -> 5 | W25: =Aggregate!AD25 -> Davante Adams | X25: =VLOOKUP(Table11[[#This Row],[NAME]],Aggregate!AD:AO,4,FALSE()) -> LAR/11 | Y25: =IFERROR(VLOOKUP(Table11[[#This Row],[NAME]],Aggregate!$AD:$AO,8,FALSE()),"") -> 150.38957 | Z25: =IF(Scoring!$K$6="Auction",IFERROR(VLOOKUP(Table11[[#This Row],[NAME]],Aggregate!$AD:$AO,10,FALSE()),""),IFERROR(VLOOKUP(Table11[[#This Row],[NAME]],Aggregate!$AD:$AO,9,FALSE()),"")) -> 24.711692 | AA25: =SUMIFS(AD26:$AD$84,AC26:$AC$84,"<>x",AC26:$AC$84,"<>o",AD26:$AD$84,">0")/Aggregate!$AL$1 -> 0.091812364 | AB25: =VLOOKUP(Table11[[#This Row],[NAME]],ECR!C:E,3,FALSE()) -> WR23 | AD25: =VLOOKUP(W25,Aggregate!AD:AL,9,FALSE()) -> 24.711692
B26: =IFERROR(VLOOKUP(Table9[[#This Row],[NAME]],Aggregate!$B:$M,11,FALSE()),"") -> 11 | C26: =Aggregate!B26 -> Daniel Jones | D26: =VLOOKUP(Table9[[#This Row],[NAME]],Aggregate!B:M,4,FALSE()) -> IND/13 | E26: =IFERROR(VLOOKUP(Table9[[#This Row],[NAME]],Aggregate!$B:$M,8,FALSE()),"") -> 219.8708 | F26: =IF(Scoring!$K$6="Auction",IFERROR(VLOOKUP(Table9[[#This Row],[NAME]],Aggregate!$B:$M,10,FALSE()),""),IFERROR(VLOOKUP(Table9[[#This Row],[NAME]],Aggregate!$B:$M,9,FALSE()),"")) -> -48.508566 | G26: =SUMIFS(J27:$J$44,I27:$I$44,"<>x",I27:$I$44,"<>o",J27:$J$44,">0")/Aggregate!$J$1 -> 0 | H26: =VLOOKUP(Table9[[#This Row],[NAME]],ECR!C:E,3,FALSE()) -> QB24 | J26: =VLOOKUP(C26,Aggregate!B:J,9,FALSE()) -> -48.508566 | L26: =IFERROR(VLOOKUP(Table10[[#This Row],[NAME]],Aggregate!$P:$AA,11,FALSE()),"") -> 5 | M26: =Aggregate!P25 -> Bhayshul Tuten | N26: =VLOOKUP(Table10[[#This Row],[NAME]],Aggregate!P:AA,4,FALSE()) -> JAC/7 | O26: =IFERROR(VLOOKUP(Table10[[#This Row],[NAME]],Aggregate!$P:$AA,8,FALSE()),"") -> 163.07169 | P26: =IF(Scoring!$K$6="Auction",IFERROR(VLOOKUP(Table10[[#This Row],[NAME]],Aggregate!$P:$AA,10,FALSE()),""),IFERROR(VLOOKUP(Table10[[#This Row],[NAME]],Aggregate!$P:$AA,9,FALSE()),"")) -> 35.525956 | Q26: =SUMIFS(T27:$T$84,S27:$S$84,"<>x",S27:$S$84,"<>o",T27:$T$84,">0")/Aggregate!$X$1 -> 0.076908282 | R26: =VLOOKUP(Table10[[#This Row],[NAME]],ECR!C:E,3,FALSE()) -> RB23 | T26: =VLOOKUP(M26,Aggregate!P:X,9,FALSE()) -> 35.525956 | V26: =IFERROR(VLOOKUP(Table11[[#This Row],[NAME]],Aggregate!$AD:$AO,11,FALSE()),"") -> 5 | W26: =Aggregate!AD19 -> Jaylen Waddle | X26: =VLOOKUP(Table11[[#This Row],[NAME]],Aggregate!AD:AO,4,FALSE()) -> DEN/10 | Y26: =IFERROR(VLOOKUP(Table11[[#This Row],[NAME]],Aggregate!$AD:$AO,8,FALSE()),"") -> 149.20195 | Z26: =IF(Scoring!$K$6="Auction",IFERROR(VLOOKUP(Table11[[#This Row],[NAME]],Aggregate!$AD:$AO,10,FALSE()),""),IFERROR(VLOOKUP(Table11[[#This Row],[NAME]],Aggregate!$AD:$AO,9,FALSE()),"")) -> 23.524067 | AA26: =SUMIFS(AD27:$AD$84,AC27:$AC$84,"<>x",AC27:$AC$84,"<>o",AD27:$AD$84,">0")/Aggregate!$AL$1 -> 0.074937513 | AB26: =VLOOKUP(Table11[[#This Row],[NAME]],ECR!C:E,3,FALSE()) -> WR17 | AD26: =VLOOKUP(W26,Aggregate!AD:AL,9,FALSE()) -> 23.524067
B27: =IFERROR(VLOOKUP(Table9[[#This Row],[NAME]],Aggregate!$B:$M,11,FALSE()),"") -> 11 | C27: =Aggregate!B24 -> Sam Darnold | D27: =VLOOKUP(Table9[[#This Row],[NAME]],Aggregate!B:M,4,FALSE()) -> SEA/11 | E27: =IFERROR(VLOOKUP(Table9[[#This Row],[NAME]],Aggregate!$B:$M,8,FALSE()),"") -> 219.87059 | F27: =IF(Scoring!$K$6="Auction",IFERROR(VLOOKUP(Table9[[#This Row],[NAME]],Aggregate!$B:$M,10,FALSE()),""),IFERROR(VLOOKUP(Table9[[#This Row],[NAME]],Aggregate!$B:$M,9,FALSE()),"")) -> -48.508776 | G27: =SUMIFS(J28:$J$44,I28:$I$44,"<>x",I28:$I$44,"<>o",J28:$J$44,">0")/Aggregate!$J$1 -> 0 | H27: =VLOOKUP(Table9[[#This Row],[NAME]],ECR!C:E,3,FALSE()) -> QB22 | J27: =VLOOKUP(C27,Aggregate!B:J,9,FALSE()) -> -48.508776 | L27: =IFERROR(VLOOKUP(Table10[[#This Row],[NAME]],Aggregate!$P:$AA,11,FALSE()),"") -> 5 | M27: =Aggregate!P26 -> Jadarian Price | N27: =VLOOKUP(Table10[[#This Row],[NAME]],Aggregate!P:AA,4,FALSE()) -> SEA/11 | O27: =IFERROR(VLOOKUP(Table10[[#This Row],[NAME]],Aggregate!$P:$AA,8,FALSE()),"") -> 159.01824 | P27: =IF(Scoring!$K$6="Auction",IFERROR(VLOOKUP(Table10[[#This Row],[NAME]],Aggregate!$P:$AA,10,FALSE()),""),IFERROR(VLOOKUP(Table10[[#This Row],[NAME]],Aggregate!$P:$AA,9,FALSE()),"")) -> 31.472501 | Q27: =SUMIFS(T28:$T$84,S28:$S$84,"<>x",S28:$S$84,"<>o",T28:$T$84,">0")/Aggregate!$X$1 -> 0.059908213 | R27: =VLOOKUP(Table10[[#This Row],[NAME]],ECR!C:E,3,FALSE()) -> RB24 | T27: =VLOOKUP(M27,Aggregate!P:X,9,FALSE()) -> 31.472501 | V27: =IFERROR(VLOOKUP(Table11[[#This Row],[NAME]],Aggregate!$AD:$AO,11,FALSE()),"") -> 5 | W27: =Aggregate!AD27 -> Jameson Williams | X27: =VLOOKUP(Table11[[#This Row],[NAME]],Aggregate!AD:AO,4,FALSE()) -> DET/6 | Y27: =IFERROR(VLOOKUP(Table11[[#This Row],[NAME]],Aggregate!$AD:$AO,8,FALSE()),"") -> 145.97952 | Z27: =IF(Scoring!$K$6="Auction",IFERROR(VLOOKUP(Table11[[#This Row],[NAME]],Aggregate!$AD:$AO,10,FALSE()),""),IFERROR(VLOOKUP(Table11[[#This Row],[NAME]],Aggregate!$AD:$AO,9,FALSE()),"")) -> 20.301644 | AA27: =SUMIFS(AD28:$AD$84,AC28:$AC$84,"<>x",AC28:$AC$84,"<>o",AD28:$AD$84,">0")/Aggregate!$AL$1 -> 0.060374248 | AB27: =VLOOKUP(Table11[[#This Row],[NAME]],ECR!C:E,3,FALSE()) -> WR25 | AD27: =VLOOKUP(W27,Aggregate!AD:AL,9,FALSE()) -> 20.301644
B28: =IFERROR(VLOOKUP(Table9[[#This Row],[NAME]],Aggregate!$B:$M,11,FALSE()),"") -> 12 | C28: =Aggregate!B25 -> C.J. Stroud | D28: =VLOOKUP(Table9[[#This Row],[NAME]],Aggregate!B:M,4,FALSE()) -> HOU/8 | E28: =IFERROR(VLOOKUP(Table9[[#This Row],[NAME]],Aggregate!$B:$M,8,FALSE()),"") -> 214.51287 | F28: =IF(Scoring!$K$6="Auction",IFERROR(VLOOKUP(Table9[[#This Row],[NAME]],Aggregate!$B:$M,10,FALSE()),""),IFERROR(VLOOKUP(Table9[[#This Row],[NAME]],Aggregate!$B:$M,9,FALSE()),"")) -> -53.866492 | G28: =SUMIFS(J29:$J$44,I29:$I$44,"<>x",I29:$I$44,"<>o",J29:$J$44,">0")/Aggregate!$J$1 -> 0 | H28: =VLOOKUP(Table9[[#This Row],[NAME]],ECR!C:E,3,FALSE()) -> QB23 | J28: =VLOOKUP(C28,Aggregate!B:J,9,FALSE()) -> -53.866492 | L28: =IFERROR(VLOOKUP(Table10[[#This Row],[NAME]],Aggregate!$P:$AA,11,FALSE()),"") -> 5 | M28: =Aggregate!P23 -> David Montgomery | N28: =VLOOKUP(Table10[[#This Row],[NAME]],Aggregate!P:AA,4,FALSE()) -> HOU/8 | O28: =IFERROR(VLOOKUP(Table10[[#This Row],[NAME]],Aggregate!$P:$AA,8,FALSE()),"") -> 158.11561 | P28: =IF(Scoring!$K$6="Auction",IFERROR(VLOOKUP(Table10[[#This Row],[NAME]],Aggregate!$P:$AA,10,FALSE()),""),IFERROR(VLOOKUP(Table10[[#This Row],[NAME]],Aggregate!$P:$AA,9,FALSE()),"")) -> 30.569875 | Q28: =SUMIFS(T29:$T$84,S29:$S$84,"<>x",S29:$S$84,"<>o",T29:$T$84,">0")/Aggregate!$X$1 -> 0.043395703 | R28: =VLOOKUP(Table10[[#This Row],[NAME]],ECR!C:E,3,FALSE()) -> RB21 | T28: =VLOOKUP(M28,Aggregate!P:X,9,FALSE()) -> 30.569875 | V28: =IFERROR(VLOOKUP(Table11[[#This Row],[NAME]],Aggregate!$AD:$AO,11,FALSE()),"") -> 5 | W28: =Aggregate!AD26 -> Terry McLaurin | X28: =VLOOKUP(Table11[[#This Row],[NAME]],Aggregate!AD:AO,4,FALSE()) -> WAS/7 | Y28: =IFERROR(VLOOKUP(Table11[[#This Row],[NAME]],Aggregate!$AD:$AO,8,FALSE()),"") -> 143.83584 | Z28: =IF(Scoring!$K$6="Auction",IFERROR(VLOOKUP(Table11[[#This Row],[NAME]],Aggregate!$AD:$AO,10,FALSE()),""),IFERROR(VLOOKUP(Table11[[#This Row],[NAME]],Aggregate!$AD:$AO,9,FALSE()),"")) -> 18.157963 | AA28: =SUMIFS(AD29:$AD$84,AC29:$AC$84,"<>x",AC29:$AC$84,"<>o",AD29:$AD$84,">0")/Aggregate!$AL$1 -> 0.04734874 | AB28: =VLOOKUP(Table11[[#This Row],[NAME]],ECR!C:E,3,FALSE()) -> WR24 | AD28: =VLOOKUP(W28,Aggregate!AD:AL,9,FALSE()) -> 18.157963
